Workbook
Name calculatedNo: Calculations!$S$20
Name calculatedYes: Calculations!$S$4
Name habitlist: 'Habit List'!$B$4:$B$13
Name selectedHabit: Dashboard!$B$4
Name selectedMonth: Dashboard!$D$4

Sheet Habit List
B1: Habit List
B3: My Habits | C3: YES | D3: NO | E3: %
B4: Habit 1 | C4: =SUM(JAN:DEC!AI4) -> 93 | D4: =SUM(JAN:DEC!AJ4) -> 2 | E4: =IF(C4+D4=0,0,C4/(C4+D4)) -> 0.97894737
B5: Habit 2 | C5: =SUM(JAN:DEC!AI5) -> 91 | D5: =SUM(JAN:DEC!AJ5) -> 1 | E5: =IF(C5+D5=0,0,C5/(C5+D5)) -> 0.98913043
B6: Habit 3 | C6: =SUM(JAN:DEC!AI6) -> 91 | D6: =SUM(JAN:DEC!AJ6) -> 1 | E6: =IF(C6+D6=0,0,C6/(C6+D6)) -> 0.98913043
B7: Habit 4 | C7: =SUM(JAN:DEC!AI7) -> 91 | D7: =SUM(JAN:DEC!AJ7) -> 1 | E7: =IF(C7+D7=0,0,C7/(C7+D7)) -> 0.98913043
B8: Habit 5 | C8: =SUM(JAN:DEC!AI8) -> 92 | D8: =SUM(JAN:DEC!AJ8) -> 2 | E8: =IF(C8+D8=0,0,C8/(C8+D8)) -> 0.9787234
B9: Habit 6 | C9: =SUM(JAN:DEC!AI9) -> 91 | D9: =SUM(JAN:DEC!AJ9) -> 1 | E9: =IF(C9+D9=0,0,C9/(C9+D9)) -> 0.98913043
B10: Habit 7 | C10: =SUM(JAN:DEC!AI10) -> 91 | D10: =SUM(JAN:DEC!AJ10) -> 1 | E10: =IF(C10+D10=0,0,C10/(C10+D10)) -> 0.98913043
B11: Habit 8 | C11: =SUM(JAN:DEC!AI11) -> 91 | D11: =SUM(JAN:DEC!AJ11) -> 1 | E11: =IF(C11+D11=0,0,C11/(C11+D11)) -> 0.98913043
B12: Habit 9 | C12: =SUM(JAN:DEC!AI12) -> 91 | D12: =SUM(JAN:DEC!AJ12) -> 1 | E12: =IF(C12+D12=0,0,C12/(C12+D12)) -> 0.98913043
B13: Habit 10 | C13: =SUM(JAN:DEC!AI13) -> 91 | D13: =SUM(JAN:DEC!AJ13) -> 1 | E13: =IF(C13+D13=0,0,C13/(C13+D13)) -> 0.98913043

Sheet Calculations
B1: Calculations
C3: YES
C4: JAN | D4: FEB | E4: MAR | F4: APR | G4: MAY | H4: JUN | I4: JUL | J4: AUG | K4: SEP | L4: OCT | M4: NOV | N4: DEC | P4: TOTAL | R4: YES | S4: {=_xlfn.IFS(AND(ISBLANK(selectedHabit),ISBLANK(selectedMonth)),SUM(P5:P14), ISBLANK(selectedHabit),INDEX(C16:N16,1,MATCH(selectedMonth,C4:N4,0)), ISBLANK(selectedMonth),INDEX(P5:P14,MATCH(selectedHabit,_xlfn.ANCHORARRAY(B5),0)), 1,INDEX(C5:N14,MATCH(selectedHabit,_xlfn.ANCHORARRAY(B5),0),MATCH(selectedMonth,C4:N4,0)))} -> 3
B5: {=habitlist} -> Habit 1 | C5: =JAN!AI4 -> 5 | D5: =FEB!AI4 -> 8 | E5: =MAR!AI4 -> 8 | F5: =APR!AI4 -> 8 | G5: =MAY!AI4 -> 8 | H5: =JUN!AI4 -> 8 | I5: =JUL!AI4 -> 8 | J5: =AUG!AI4 -> 8 | K5: =SEP!AI4 -> 8 | L5: =OCT!AI4 -> 8 | M5: =NOV!AI4 -> 8 | N5: =DEC!AI4 -> 8 | P5: =SUM(C5:N5) -> 93
B6: Habit 2 | C6: =JAN!AI5 -> 3 | D6: =FEB!AI5 -> 8 | E6: =MAR!AI5 -> 8 | F6: =APR!AI5 -> 8 | G6: =MAY!AI5 -> 8 | H6: =JUN!AI5 -> 8 | I6: =JUL!AI5 -> 8 | J6: =AUG!AI5 -> 8 | K6: =SEP!AI5 -> 8 | L6: =OCT!AI5 -> 8 | M6: =NOV!AI5 -> 8 | N6: =DEC!AI5 -> 8 | P6: =SUM(C6:N6) -> 91
B7: Habit 3 | C7: =JAN!AI6 -> 3 | D7: =FEB!AI6 -> 8 | E7: =MAR!AI6 -> 8 | F7: =APR!AI6 -> 8 | G7: =MAY!AI6 -> 8 | H7: =JUN!AI6 -> 8 | I7: =JUL!AI6 -> 8 | J7: =AUG!AI6 -> 8 | K7: =SEP!AI6 -> 8 | L7: =OCT!AI6 -> 8 | M7: =NOV!AI6 -> 8 | N7: =DEC!AI6 -> 8 | P7: =SUM(C7:N7) -> 91
B8: Habit 4 | C8: =JAN!AI7 -> 3 | D8: =FEB!AI7 -> 8 | E8: =MAR!AI7 -> 8 | F8: =APR!AI7 -> 8 | G8: =MAY!AI7 -> 8 | H8: =JUN!AI7 -> 8 | I8: =JUL!AI7 -> 8 | J8: =AUG!AI7 -> 8 | K8: =SEP!AI7 -> 8 | L8: =OCT!AI7 -> 8 | M8: =NOV!AI7 -> 8 | N8: =DEC!AI7 -> 8 | P8: =SUM(C8:N8) -> 91
B9: Habit 5 | C9: =JAN!AI8 -> 3 | D9: =FEB!AI8 -> 8 | E9: =MAR!AI8 -> 8 | F9: =APR!AI8 -> 9 | G9: =MAY!AI8 -> 8 | H9: =JUN!AI8 -> 8 | I9: =JUL!AI8 -> 8 | J9: =AUG!AI8 -> 8 | K9: =SEP!AI8 -> 8 | L9: =OCT!AI8 -> 8 | M9: =NOV!AI8 -> 8 | N9: =DEC!AI8 -> 8 | P9: =SUM(C9:N9) -> 92
B10: Habit 6 | C10: =JAN!AI9 -> 3 | D10: =FEB!AI9 -> 8 | E10: =MAR!AI9 -> 8 | F10: =APR!AI9 -> 8 | G10: =MAY!AI9 -> 8 | H10: =JUN!AI9 -> 8 | I10: =JUL!AI9 -> 8 | J10: =AUG!AI9 -> 8 | K10: =SEP!AI9 -> 8 | L10: =OCT!AI9 -> 8 | M10: =NOV!AI9 -> 8 | N10: =DEC!AI9 -> 8 | P10: =SUM(C10:N10) -> 91
B11: Habit 7 | C11: =JAN!AI10 -> 3 | D11: =FEB!AI10 -> 8 | E11: =MAR!AI10 -> 8 | F11: =APR!AI10 -> 8 | G11: =MAY!AI10 -> 8 | H11: =JUN!AI10 -> 8 | I11: =JUL!AI10 -> 8 | J11: =AUG!AI10 -> 8 | K11: =SEP!AI10 -> 8 | L11: =OCT!AI10 -> 8 | M11: =NOV!AI10 -> 8 | N11: =DEC!AI10 -> 8 | P11: =SUM(C11:N11) -> 91
B12: Habit 8 | C12: =JAN!AI11 -> 3 | D12: =FEB!AI11 -> 8 | E12: =MAR!AI11 -> 8 | F12: =APR!AI11 -> 8 | G12: =MAY!AI11 -> 8 | H12: =JUN!AI11 -> 8 | I12: =JUL!AI11 -> 8 | J12: =AUG!AI11 -> 8 | K12: =SEP!AI11 -> 8 | L12: =OCT!AI11 -> 8 | M12: =NOV!AI11 -> 8 | N12: =DEC!AI11 -> 8 | P12: =SUM(C12:N12) -> 91
B13: Habit 9 | C13: =JAN!AI12 -> 3 | D13: =FEB!AI12 -> 8 | E13: =MAR!AI12 -> 8 | F13: =APR!AI12 -> 8 | G13: =MAY!AI12 -> 8 | H13: =JUN!AI12 -> 8 | I13: =JUL!AI12 -> 8 | J13: =AUG!AI12 -> 8 | K13: =SEP!AI12 -> 8 | L13: =OCT!AI12 -> 8 | M13: =NOV!AI12 -> 8 | N13: =DEC!AI12 -> 8 | P13: =SUM(C13:N13) -> 91
B14: Habit 10 | C14: =JAN!AI13 -> 3 | D14: =FEB!AI13 -> 8 | E14: =MAR!AI13 -> 8 | F14: =APR!AI13 -> 8 | G14: =MAY!AI13 -> 8 | H14: =JUN!AI13 -> 8 | I14: =JUL!AI13 -> 8 | J14: =AUG!AI13 -> 8 | K14: =SEP!AI13 -> 8 | L14: =OCT!AI13 -> 8 | M14: =NOV!AI13 -> 8 | N14: =DEC!AI13 -> 8 | P14: =SUM(C14:N14) -> 91
B16: TOTAL | C16: =SUM(C5:C14) -> 32 | D16: =SUM(D5:D14) -> 80 | E16: =SUM(E5:E14) -> 80 | F16: =SUM(F5:F14) -> 81 | G16: =SUM(G5:G14) -> 80 | H16: =SUM(H5:H14) -> 80 | I16: =SUM(I5:I14) -> 80 | J16: =SUM(J5:J14) -> 80 | ... N16: =SUM(N5:N14) -> 80
C19: NO
C20: JAN | D20: FEB | E20: MAR | F20: APR | G20: MAY | H20: JUN | I20: JUL | J20: AUG | K20: SEP | L20: OCT | M20: NOV | N20: DEC | P20: TOTAL | R20: NO | S20: {=_xlfn.IFS(AND(ISBLANK(selectedHabit),ISBLANK(selectedMonth)),SUM(P21:P30), ISBLANK(selectedHabit),INDEX(C32:N32,1,MATCH(selectedMonth,C20:N20,0)), ISBLANK(selectedMonth),INDEX(P21:P30,MATCH(selectedHabit,_xlfn.ANCHORARRAY(B21),0)), 1,INDEX(C21:N30,MATCH(selectedHabit,_xlfn.ANCHORARRAY(B21),0),MATCH(selectedMonth,C20:N20,0)))} -> 1
B21: {=habitlist} -> Habit 1 | C21: =JAN!AJ4 -> 2 | D21: =FEB!AJ4 -> 0 | E21: =MAR!AJ4 -> 0 | F21: =APR!AJ4 -> 0 | G21: =MAY!AJ4 -> 0 | H21: =JUN!AJ4 -> 0 | I21: =JUL!AJ4 -> 0 | J21: =AUG!AJ4 -> 0 | K21: =SEP!AJ4 -> 0 | L21: =OCT!AJ4 -> 0 | M21: =NOV!AJ4 -> 0 | N21: =DEC!AJ4 -> 0 | P21: =SUM(C21:N21) -> 2
B22: Habit 2 | C22: =JAN!AJ5 -> 1 | D22: =FEB!AJ5 -> 0 | E22: =MAR!AJ5 -> 0 | F22: =APR!AJ5 -> 0 | G22: =MAY!AJ5 -> 0 | H22: =JUN!AJ5 -> 0 | I22: =JUL!AJ5 -> 0 | J22: =AUG!AJ5 -> 0 | K22: =SEP!AJ5 -> 0 | L22: =OCT!AJ5 -> 0 | M22: =NOV!AJ5 -> 0 | N22: =DEC!AJ5 -> 0 | P22: =SUM(C22:N22) -> 1
B23: Habit 3 | C23: =JAN!AJ6 -> 1 | D23: =FEB!AJ6 -> 0 | E23: =MAR!AJ6 -> 0 | F23: =APR!AJ6 -> 0 | G23: =MAY!AJ6 -> 0 | H23: =JUN!AJ6 -> 0 | I23: =JUL!AJ6 -> 0 | J23: =AUG!AJ6 -> 0 | K23: =SEP!AJ6 -> 0 | L23: =OCT!AJ6 -> 0 | M23: =NOV!AJ6 -> 0 | N23: =DEC!AJ6 -> 0 | P23: =SUM(C23:N23) -> 1
B24: Habit 4 | C24: =JAN!AJ7 -> 1 | D24: =FEB!AJ7 -> 0 | E24: =MAR!AJ7 -> 0 | F24: =APR!AJ7 -> 0 | G24: =MAY!AJ7 -> 0 | H24: =JUN!AJ7 -> 0 | I24: =JUL!AJ7 -> 0 | J24: =AUG!AJ7 -> 0 | K24: =SEP!AJ7 -> 0 | L24: =OCT!AJ7 -> 0 | M24: =NOV!AJ7 -> 0 | N24: =DEC!AJ7 -> 0 | P24: =SUM(C24:N24) -> 1
B25: Habit 5 | C25: =JAN!AJ8 -> 1 | D25: =FEB!AJ8 -> 0 | E25: =MAR!AJ8 -> 0 | F25: =APR!AJ8 -> 1 | G25: =MAY!AJ8 -> 0 | H25: =JUN!AJ8 -> 0 | I25: =JUL!AJ8 -> 0 | J25: =AUG!AJ8 -> 0 | K25: =SEP!AJ8 -> 0 | L25: =OCT!AJ8 -> 0 | M25: =NOV!AJ8 -> 0 | N25: =DEC!AJ8 -> 0 | P25: =SUM(C25:N25) -> 2
B26: Habit 6 | C26: =JAN!AJ9 -> 1 | D26: =FEB!AJ9 -> 0 | E26: =MAR!AJ9 -> 0 | F26: =APR!AJ9 -> 0 | G26: =MAY!AJ9 -> 0 | H26: =JUN!AJ9 -> 0 | I26: =JUL!AJ9 -> 0 | J26: =AUG!AJ9 -> 0 | K26: =SEP!AJ9 -> 0 | L26: =OCT!AJ9 -> 0 | M26: =NOV!AJ9 -> 0 | N26: =DEC!AJ9 -> 0 | P26: =SUM(C26:N26) -> 1
B27: Habit 7 | C27: =JAN!AJ10 -> 1 | D27: =FEB!AJ10 -> 0 | E27: =MAR!AJ10 -> 0 | F27: =APR!AJ10 -> 0 | G27: =MAY!AJ10 -> 0 | H27: =JUN!AJ10 -> 0 | I27: =JUL!AJ10 -> 0 | J27: =AUG!AJ10 -> 0 | K27: =SEP!AJ10 -> 0 | L27: =OCT!AJ10 -> 0 | M27: =NOV!AJ10 -> 0 | N27: =DEC!AJ10 -> 0 | P27: =SUM(C27:N27) -> 1
B28: Habit 8 | C28: =JAN!AJ11 -> 1 | D28: =FEB!AJ11 -> 0 | E28: =MAR!AJ11 -> 0 | F28: =APR!AJ11 -> 0 | G28: =MAY!AJ11 -> 0 | H28: =JUN!AJ11 -> 0 | I28: =JUL!AJ11 -> 0 | J28: =AUG!AJ11 -> 0 | K28: =SEP!AJ11 -> 0 | L28: =OCT!AJ11 -> 0 | M28: =NOV!AJ11 -> 0 | N28: =DEC!AJ11 -> 0 | P28: =SUM(C28:N28) -> 1
B29: Habit 9 | C29: =JAN!AJ12 -> 1 | D29: =FEB!AJ12 -> 0 | E29: =MAR!AJ12 -> 0 | F29: =APR!AJ12 -> 0 | G29: =MAY!AJ12 -> 0 | H29: =JUN!AJ12 -> 0 | I29: =JUL!AJ12 -> 0 | J29: =AUG!AJ12 -> 0 | K29: =SEP!AJ12 -> 0 | L29: =OCT!AJ12 -> 0 | M29: =NOV!AJ12 -> 0 | N29: =DEC!AJ12 -> 0 | P29: =SUM(C29:N29) -> 1
B30: Habit 10 | C30: =JAN!AJ13 -> 1 | D30: =FEB!AJ13 -> 0 | E30: =MAR!AJ13 -> 0 | F30: =APR!AJ13 -> 0 | G30: =MAY!AJ13 -> 0 | H30: =JUN!AJ13 -> 0 | I30: =JUL!AJ13 -> 0 | J30: =AUG!AJ13 -> 0 | K30: =SEP!AJ13 -> 0 | L30: =OCT!AJ13 -> 0 | M30: =NOV!AJ13 -> 0 | N30: =DEC!AJ13 -> 0 | P30: =SUM(C30:N30) -> 1
B32: TOTAL | C32: =SUM(C21:C30) -> 11 | D32: =SUM(D21:D30) -> 0 | E32: =SUM(E21:E30) -> 0 | F32: =SUM(F21:F30) -> 1 | G32: =SUM(G21:G30) -> 0 | H32: =SUM(H21:H30) -> 0 | I32: =SUM(I21:I30) -> 0 | J32: =SUM(J21:J30) -> 0 | ... N32: =SUM(N21:N30) -> 0
C35: PERCENT
C36: JAN | D36: FEB | E36: MAR | F36: APR | G36: MAY | H36: JUN | I36: JUL | J36: AUG | K36: SEP | L36: OCT | M36: NOV | N36: DEC | P36: TOTAL | R36: CHART
B37: {=habitlist} -> Habit 1 | C37: =IF(C5+C21=0, NA(),C5/(C5+C21)) -> 0.71428571 | D37: =IF(D5+D21=0, NA(),D5/(D5+D21)) -> 1 | E37: =IF(E5+E21=0, NA(),E5/(E5+E21)) -> 1 | F37: =IF(F5+F21=0, NA(),F5/(F5+F21)) -> 1 | G37: =IF(G5+G21=0, NA(),G5/(G5+G21)) -> 1 | H37: =IF(H5+H21=0, NA(),H5/(H5+H21)) -> 1 | I37: =IF(I5+I21=0, NA(),I5/(I5+I21)) -> 1 | J37: =IF(J5+J21=0, NA(),J5/(J5+J21)) -> 1 | ... N37: =IF(N5+N21=0, NA(),N5/(N5+N21)) -> 1 | P37: =AVERAGE(C37:N37) -> 0.97619048 | R37: =IF(ISBLANK(selectedMonth),P37,INDEX(C37:N37,1,MATCH(selectedMonth,$C$36:$N$36,0))) -> 0.71428571
B38: Habit 2 | C38: =IF(C6+C22=0, NA(),C6/(C6+C22)) -> 0.75 | D38: =IF(D6+D22=0, NA(),D6/(D6+D22)) -> 1 | E38: =IF(E6+E22=0, NA(),E6/(E6+E22)) -> 1 | F38: =IF(F6+F22=0, NA(),F6/(F6+F22)) -> 1 | G38: =IF(G6+G22=0, NA(),G6/(G6+G22)) -> 1 | H38: =IF(H6+H22=0, NA(),H6/(H6+H22)) -> 1 | I38: =IF(I6+I22=0, NA(),I6/(I6+I22)) -> 1 | J38: =IF(J6+J22=0, NA(),J6/(J6+J22)) -> 1 | ... N38: =IF(N6+N22=0, NA(),N6/(N6+N22)) -> 1 | P38: =AVERAGE(C38:N38) -> 0.97916667 | R38: =IF(ISBLANK(selectedMonth),P38,INDEX(C38:N38,1,MATCH(selectedMonth,$C$36:$N$36,0))) -> 0.75
B39: Habit 3 | C39: =IF(C7+C23=0, NA(),C7/(C7+C23)) -> 0.75 | D39: =IF(D7+D23=0, NA(),D7/(D7+D23)) -> 1 | E39: =IF(E7+E23=0, NA(),E7/(E7+E23)) -> 1 | F39: =IF(F7+F23=0, NA(),F7/(F7+F23)) -> 1 | G39: =IF(G7+G23=0, NA(),G7/(G7+G23)) -> 1 | H39: =IF(H7+H23=0, NA(),H7/(H7+H23)) -> 1 | I39: =IF(I7+I23=0, NA(),I7/(I7+I23)) -> 1 | J39: =IF(J7+J23=0, NA(),J7/(J7+J23)) -> 1 | ... N39: =IF(N7+N23=0, NA(),N7/(N7+N23)) -> 1 | P39: =AVERAGE(C39:N39) -> 0.97916667 | R39: =IF(ISBLANK(selectedMonth),P39,INDEX(C39:N39,1,MATCH(selectedMonth,$C$36:$N$36,0))) -> 0.75
B40: Habit 4 | C40: =IF(C8+C24=0, NA(),C8/(C8+C24)) -> 0.75 | D40: =IF(D8+D24=0, NA(),D8/(D8+D24)) -> 1 | E40: =IF(E8+E24=0, NA(),E8/(E8+E24)) -> 1 | F40: =IF(F8+F24=0, NA(),F8/(F8+F24)) -> 1 | G40: =IF(G8+G24=0, NA(),G8/(G8+G24)) -> 1 | H40: =IF(H8+H24=0, NA(),H8/(H8+H24)) -> 1 | I40: =IF(I8+I24=0, NA(),I8/(I8+I24)) -> 1 | J40: =IF(J8+J24=0, NA(),J8/(J8+J24)) -> 1 | ... N40: =IF(N8+N24=0, NA(),N8/(N8+N24)) -> 1 | P40: =AVERAGE(C40:N40) -> 0.97916667 | R40: =IF(ISBLANK(selectedMonth),P40,INDEX(C40:N40,1,MATCH(selectedMonth,$C$36:$N$36,0))) -> 0.75
B41: Habit 5 | C41: =IF(C9+C25=0, NA(),C9/(C9+C25)) -> 0.75 | D41: =IF(D9+D25=0, NA(),D9/(D9+D25)) -> 1 | E41: =IF(E9+E25=0, NA(),E9/(E9+E25)) -> 1 | F41: =IF(F9+F25=0, NA(),F9/(F9+F25)) -> 0.9 | G41: =IF(G9+G25=0, NA(),G9/(G9+G25)) -> 1 | H41: =IF(H9+H25=0, NA(),H9/(H9+H25)) -> 1 | I41: =IF(I9+I25=0, NA(),I9/(I9+I25)) -> 1 | J41: =IF(J9+J25=0, NA(),J9/(J9+J25)) -> 1 | ... N41: =IF(N9+N25=0, NA(),N9/(N9+N25)) -> 1 | P41: =AVERAGE(C41:N41) -> 0.97083333 | R41: =IF(ISBLANK(selectedMonth),P41,INDEX(C41:N41,1,MATCH(selectedMonth,$C$36:$N$36,0))) -> 0.75
B42: Habit 6 | C42: =IF(C10+C26=0, NA(),C10/(C10+C26)) -> 0.75 | D42: =IF(D10+D26=0, NA(),D10/(D10+D26)) -> 1 | E42: =IF(E10+E26=0, NA(),E10/(E10+E26)) -> 1 | F42: =IF(F10+F26=0, NA(),F10/(F10+F26)) -> 1 | G42: =IF(G10+G26=0, NA(),G10/(G10+G26)) -> 1 | H42: =IF(H10+H26=0, NA(),H10/(H10+H26)) -> 1 | I42: =IF(I10+I26=0, NA(),I10/(I10+I26)) -> 1 | J42: =IF(J10+J26=0, NA(),J10/(J10+J26)) -> 1 | ... N42: =IF(N10+N26=0, NA(),N10/(N10+N26)) -> 1 | P42: =AVERAGE(C42:N42) -> 0.97916667 | R42: =IF(ISBLANK(selectedMonth),P42,INDEX(C42:N42,1,MATCH(selectedMonth,$C$36:$N$36,0))) -> 0.75
B43: Habit 7 | C43: =IF(C11+C27=0, NA(),C11/(C11+C27)) -> 0.75 | D43: =IF(D11+D27=0, NA(),D11/(D11+D27)) -> 1 | E43: =IF(E11+E27=0, NA(),E11/(E11+E27)) -> 1 | F43: =IF(F11+F27=0, NA(),F11/(F11+F27)) -> 1 | G43: =IF(G11+G27=0, NA(),G11/(G11+G27)) -> 1 | H43: =IF(H11+H27=0, NA(),H11/(H11+H27)) -> 1 | I43: =IF(I11+I27=0, NA(),I11/(I11+I27)) -> 1 | J43: =IF(J11+J27=0, NA(),J11/(J11+J27)) -> 1 | ... N43: =IF(N11+N27=0, NA(),N11/(N11+N27)) -> 1 | P43: =AVERAGE(C43:N43) -> 0.97916667 | R43: =IF(ISBLANK(selectedMonth),P43,INDEX(C43:N43,1,MATCH(selectedMonth,$C$36:$N$36,0))) -> 0.75
B44: Habit 8 | C44: =IF(C12+C28=0, NA(),C12/(C12+C28)) -> 0.75 | D44: =IF(D12+D28=0, NA(),D12/(D12+D28)) -> 1 | E44: =IF(E12+E28=0, NA(),E12/(E12+E28)) -> 1 | F44: =IF(F12+F28=0, NA(),F12/(F12+F28)) -> 1 | G44: =IF(G12+G28=0, NA(),G12/(G12+G28)) -> 1 | H44: =IF(H12+H28=0, NA(),H12/(H12+H28)) -> 1 | I44: =IF(I12+I28=0, NA(),I12/(I12+I28)) -> 1 | J44: =IF(J12+J28=0, NA(),J12/(J12+J28)) -> 1 | ... N44: =IF(N12+N28=0, NA(),N12/(N12+N28)) -> 1 | P44: =AVERAGE(C44:N44) -> 0.97916667 | R44: =IF(ISBLANK(selectedMonth),P44,INDEX(C44:N44,1,MATCH(selectedMonth,$C$36:$N$36,0))) -> 0.75
B45: Habit 9 | C45: =IF(C13+C29=0, NA(),C13/(C13+C29)) -> 0.75 | D45: =IF(D13+D29=0, NA(),D13/(D13+D29)) -> 1 | E45: =IF(E13+E29=0, NA(),E13/(E13+E29)) -> 1 | F45: =IF(F13+F29=0, NA(),F13/(F13+F29)) -> 1 | G45: =IF(G13+G29=0, NA(),G13/(G13+G29)) -> 1 | H45: =IF(H13+H29=0, NA(),H13/(H13+H29)) -> 1 | I45: =IF(I13+I29=0, NA(),I13/(I13+I29)) -> 1 | J45: =IF(J13+J29=0, NA(),J13/(J13+J29)) -> 1 | ... N45: =IF(N13+N29=0, NA(),N13/(N13+N29)) -> 1 | P45: =AVERAGE(C45:N45) -> 0.97916667 | R45: =IF(ISBLANK(selectedMonth),P45,INDEX(C45:N45,1,MATCH(selectedMonth,$C$36:$N$36,0))) -> 0.75
B46: Habit 10 | C46: =IF(C14+C30=0, NA(),C14/(C14+C30)) -> 0.75 | D46: =IF(D14+D30=0, NA(),D14/(D14+D30)) -> 1 | E46: =IF(E14+E30=0, NA(),E14/(E14+E30)) -> 1 | F46: =IF(F14+F30=0, NA(),F14/(F14+F30)) -> 1 | G46: =IF(G14+G30=0, NA(),G14/(G14+G30)) -> 1 | H46: =IF(H14+H30=0, NA(),H14/(H14+H30)) -> 1 | I46: =IF(I14+I30=0, NA(),I14/(I14+I30)) -> 1 | J46: =IF(J14+J30=0, NA(),J14/(J14+J30)) -> 1 | ... N46: =IF(N14+N30=0, NA(),N14/(N14+N30)) -> 1 | P46: =AVERAGE(C46:N46) -> 0.97916667 | R46: =IF(ISBLANK(selectedMonth),P46,INDEX(C46:N46,1,MATCH(selectedMonth,$C$36:$N$36,0))) -> 0.75
B48: TOTAL | C48: =IF(SUM(C5:C14,C21:C30)=0,NA(),SUM(C5:C14)/SUM(C5:C14,C21:C30)) -> 0.74418605 | D48: =IF(SUM(D5:D14,D21:D30)=0,NA(),SUM(D5:D14)/SUM(D5:D14,D21:D30)) -> 1 | E48: =IF(SUM(E5:E14,E21:E30)=0,NA(),SUM(E5:E14)/SUM(E5:E14,E21:E30)) -> 1 | F48: =IF(SUM(F5:F14,F21:F30)=0,NA(),SUM(F5:F14)/SUM(F5:F14,F21:F30)) -> 0.98780488 | G48: =IF(SUM(G5:G14,G21:G30)=0,NA(),SUM(G5:G14)/SUM(G5:G14,G21:G30)) -> 1 | H48: =IF(SUM(H5:H14,H21:H30)=0,NA(),SUM(H5:H14)/SUM(H5:H14,H21:H30)) -> 1 | I48: =IF(SUM(I5:I14,I21:I30)=0,NA(),SUM(I5:I14)/SUM(I5:I14,I21:I30)) -> 1 | J48: =IF(SUM(J5:J14,J21:J30)=0,NA(),SUM(J5:J14)/SUM(J5:J14,J21:J30)) -> 1 | ... N48: =IF(SUM(N5:N14,N21:N30)=0,NA(),SUM(N5:N14)/SUM(N5:N14,N21:N30)) -> 1
...

Sheet Dashboard
B1: DASHBOARD
B3: Select Habit | D3: Select Month | G3: =IF(ISBLANK(selectedMonth),"Habit Performance - All Months","Habit Performance -"&selectedMonth) -> Habit Performance -JAN
B4: Habit 3 | D4: JAN
B6: YES | D6: NO
B7: =calculatedYes -> 3 | D7: =calculatedNo -> 1
B9: =IF(B7+D7=0,0,B7/(B7+D7)) -> 0.75 | G9: =IF(ISBLANK(selectedHabit)," All Habits Percentage",selectedHabit&"Percentage") -> Habit 3Percentage

Sheet JAN
B1: JANUARY
C3: 1 | D3: 2 | E3: 3 | F3: 4 | G3: 5 | H3: 6 | I3: 7 | J3: 8 | K3: 9 | L3: 10 | M3: 11 | N3: 12 | O3: 13 | P3: 14 | Q3: 15 | R3: 16 | S3: 17 | T3: 18 | U3: 19 | V3: 20 | W3: 21 | X3: 22 | Y3: 23 | Z3: 24 | AA3: 25 | AB3: 26 | AC3: 27 | AD3: 28 | AE3: 29 | AF3: 30 | AG3: 31 | AI3: YES | AJ3: NO
B4: {=habitlist} -> Habit 1 | C4: 1 | D4: 1 | E4: 1 | F4: 1 | G4: 1 | H4: -1 | I4: -1 | AI4: =COUNTIF(C4:AG4, ">=1") -> 5 | AJ4: =COUNTIF(C4:AG4, "<0") -> 2
B5: Habit 2 | C5: 1 | D5: 1 | F5: 1 | H5: -1 | AI5: =COUNTIF(C5:AG5, ">=1") -> 3 | AJ5: =COUNTIF(C5:AG5, "<0") -> 1
B6: Habit 3 | C6: 1 | D6: 1 | F6: 1 | H6: -1 | AI6: =COUNTIF(C6:AG6, ">=1") -> 3 | AJ6: =COUNTIF(C6:AG6, "<0") -> 1
B7: Habit 4 | C7: 1 | D7: 1 | F7: 1 | H7: -1 | AI7: =COUNTIF(C7:AG7, ">=1") -> 3 | AJ7: =COUNTIF(C7:AG7, "<0") -> 1
B8: Habit 5 | C8: 1 | D8: 1 | F8: 1 | H8: -1 | AI8: =COUNTIF(C8:AG8, ">=1") -> 3 | AJ8: =COUNTIF(C8:AG8, "<0") -> 1
B9: Habit 6 | C9: 1 | D9: 1 | F9: 1 | H9: -1 | AI9: =COUNTIF(C9:AG9, ">=1") -> 3 | AJ9: =COUNTIF(C9:AG9, "<0") -> 1
B10: Habit 7 | C10: 1 | D10: 1 | F10: 1 | H10: -1 | AI10: =COUNTIF(C10:AG10, ">=1") -> 3 | AJ10: =COUNTIF(C10:AG10, "<0") -> 1
B11: Habit 8 | C11: 1 | D11: 1 | F11: 1 | H11: -1 | AI11: =COUNTIF(C11:AG11, ">=1") -> 3 | AJ11: =COUNTIF(C11:AG11, "<0") -> 1
B12: Habit 9 | C12: 1 | D12: 1 | F12: 1 | H12: -1 | AI12: =COUNTIF(C12:AG12, ">=1") -> 3 | AJ12: =COUNTIF(C12:AG12, "<0") -> 1
B13: Habit 10 | C13: 1 | D13: 1 | F13: 1 | H13: -1 | AI13: =COUNTIF(C13:AG13, ">=1") -> 3 | AJ13: =COUNTIF(C13:AG13, "<0") -> 1

Sheet FEB
B1: FEBRUARY
C3: 1 | D3: 2 | E3: 3 | F3: 4 | G3: 5 | H3: 6 | I3: 7 | J3: 8 | K3: 9 | L3: 10 | M3: 11 | N3: 12 | O3: 13 | P3: 14 | Q3: 15 | R3: 16 | S3: 17 | T3: 18 | U3: 19 | V3: 20 | W3: 21 | X3: 22 | Y3: 23 | Z3: 24 | AA3: 25 | AB3: 26 | AC3: 27 | AD3: 28 | AE3: 29 | AF3: 30 | AG3: 31 | AI3: YES | AJ3: NO
B4: {=habitlist} -> Habit 1 | C4: 1 | D4: 1 | E4: 1 | F4: 1 | G4: 1 | H4: 1 | I4: 1 | J4: 1 | AI4: =COUNTIF(C4:AG4, ">=1") -> 8 | AJ4: =COUNTIF(C4:AG4, "<0") -> 0
B5: Habit 2 | C5: 1 | D5: 1 | E5: 1 | F5: 1 | G5: 1 | H5: 1 | I5: 1 | J5: 1 | AI5: =COUNTIF(C5:AG5, ">=1") -> 8 | AJ5: =COUNTIF(C5:AG5, "<0") -> 0
B6: Habit 3 | C6: 1 | D6: 1 | E6: 1 | F6: 1 | G6: 1 | H6: 1 | I6: 1 | J6: 1 | AI6: =COUNTIF(C6:AG6, ">=1") -> 8 | AJ6: =COUNTIF(C6:AG6, "<0") -> 0
B7: Habit 4 | C7: 1 | D7: 1 | E7: 1 | F7: 1 | G7: 1 | H7: 1 | I7: 1 | J7: 1 | AI7: =COUNTIF(C7:AG7, ">=1") -> 8 | AJ7: =COUNTIF(C7:AG7, "<0") -> 0
B8: Habit 5 | C8: 1 | D8: 1 | E8: 1 | F8: 1 | G8: 1 | H8: 1 | I8: 1 | J8: 1 | AI8: =COUNTIF(C8:AG8, ">=1") -> 8 | AJ8: =COUNTIF(C8:AG8, "<0") -> 0
B9: Habit 6 | C9: 1 | D9: 1 | E9: 1 | F9: 1 | G9: 1 | H9: 1 | I9: 1 | J9: 1 | AI9: =COUNTIF(C9:AG9, ">=1") -> 8 | AJ9: =COUNTIF(C9:AG9, "<0") -> 0
B10: Habit 7 | C10: 1 | D10: 1 | E10: 1 | F10: 1 | G10: 1 | H10: 1 | I10: 1 | J10: 1 | AI10: =COUNTIF(C10:AG10, ">=1") -> 8 | AJ10: =COUNTIF(C10:AG10, "<0") -> 0
B11: Habit 8 | C11: 1 | D11: 1 | E11: 1 | F11: 1 | G11: 1 | H11: 1 | I11: 1 | J11: 1 | AI11: =COUNTIF(C11:AG11, ">=1") -> 8 | AJ11: =COUNTIF(C11:AG11, "<0") -> 0
B12: Habit 9 | C12: 1 | D12: 1 | E12: 1 | F12: 1 | G12: 1 | H12: 1 | I12: 1 | J12: 1 | AI12: =COUNTIF(C12:AG12, ">=1") -> 8 | AJ12: =COUNTIF(C12:AG12, "<0") -> 0
B13: Habit 10 | C13: 1 | D13: 1 | E13: 1 | F13: 1 | G13: 1 | H13: 1 | I13: 1 | J13: 1 | AI13: =COUNTIF(C13:AG13, ">=1") -> 8 | AJ13: =COUNTIF(C13:AG13, "<0") -> 0

Sheet MAR
B1: MARCH
C3: 1 | D3: 2 | E3: 3 | F3: 4 | G3: 5 | H3: 6 | I3: 7 | J3: 8 | K3: 9 | L3: 10 | M3: 11 | N3: 12 | O3: 13 | P3: 14 | Q3: 15 | R3: 16 | S3: 17 | T3: 18 | U3: 19 | V3: 20 | W3: 21 | X3: 22 | Y3: 23 | Z3: 24 | AA3: 25 | AB3: 26 | AC3: 27 | AD3: 28 | AE3: 29 | AF3: 30 | AG3: 31 | AI3: YES | AJ3: NO
B4: {=habitlist} -> Habit 1 | C4: 1 | D4: 1 | E4: 1 | F4: 1 | G4: 1 | H4: 1 | I4: 1 | J4: 1 | AI4: =COUNTIF(C4:AG4, ">=1") -> 8 | AJ4: =COUNTIF(C4:AG4, "<0") -> 0
B5: Habit 2 | C5: 1 | D5: 1 | E5: 1 | F5: 1 | G5: 1 | H5: 1 | I5: 1 | J5: 1 | AI5: =COUNTIF(C5:AG5, ">=1") -> 8 | AJ5: =COUNTIF(C5:AG5, "<0") -> 0
B6: Habit 3 | C6: 1 | D6: 1 | E6: 1 | F6: 1 | G6: 1 | H6: 1 | I6: 1 | J6: 1 | AI6: =COUNTIF(C6:AG6, ">=1") -> 8 | AJ6: =COUNTIF(C6:AG6, "<0") -> 0
B7: Habit 4 | C7: 1 | D7: 1 | E7: 1 | F7: 1 | G7: 1 | H7: 1 | I7: 1 | J7: 1 | AI7: =COUNTIF(C7:AG7, ">=1") -> 8 | AJ7: =COUNTIF(C7:AG7, "<0") -> 0
B8: Habit 5 | C8: 1 | D8: 1 | E8: 1 | F8: 1 | G8: 1 | H8: 1 | I8: 1 | J8: 1 | AI8: =COUNTIF(C8:AG8, ">=1") -> 8 | AJ8: =COUNTIF(C8:AG8, "<0") -> 0
B9: Habit 6 | C9: 1 | D9: 1 | E9: 1 | F9: 1 | G9: 1 | H9: 1 | I9: 1 | J9: 1 | AI9: =COUNTIF(C9:AG9, ">=1") -> 8 | AJ9: =COUNTIF(C9:AG9, "<0") -> 0
B10: Habit 7 | C10: 1 | D10: 1 | E10: 1 | F10: 1 | G10: 1 | H10: 1 | I10: 1 | J10: 1 | AI10: =COUNTIF(C10:AG10, ">=1") -> 8 | AJ10: =COUNTIF(C10:AG10, "<0") -> 0
B11: Habit 8 | C11: 1 | D11: 1 | E11: 1 | F11: 1 | G11: 1 | H11: 1 | I11: 1 | J11: 1 | AI11: =COUNTIF(C11:AG11, ">=1") -> 8 | AJ11: =COUNTIF(C11:AG11, "<0") -> 0
B12: Habit 9 | C12: 1 | D12: 1 | E12: 1 | F12: 1 | G12: 1 | H12: 1 | I12: 1 | J12: 1 | AI12: =COUNTIF(C12:AG12, ">=1") -> 8 | AJ12: =COUNTIF(C12:AG12, "<0") -> 0
B13: Habit 10 | C13: 1 | D13: 1 | E13: 1 | F13: 1 | G13: 1 | H13: 1 | I13: 1 | J13: 1 | AI13: =COUNTIF(C13:AG13, ">=1") -> 8 | AJ13: =COUNTIF(C13:AG13, "<0") -> 0

Sheet APR
B1: APRIL
C3: 1 | D3: 2 | E3: 3 | F3: 4 | G3: 5 | H3: 6 | I3: 7 | J3: 8 | K3: 9 | L3: 10 | M3: 11 | N3: 12 | O3: 13 | P3: 14 | Q3: 15 | R3: 16 | S3: 17 | T3: 18 | U3: 19 | V3: 20 | W3: 21 | X3: 22 | Y3: 23 | Z3: 24 | AA3: 25 | AB3: 26 | AC3: 27 | AD3: 28 | AE3: 29 | AF3: 30 | AG3: 31 | AI3: YES | AJ3: NO
B4: {=habitlist} -> Habit 1 | C4: 1 | D4: 1 | E4: 1 | F4: 1 | G4: 1 | H4: 1 | I4: 1 | J4: 1 | AI4: =COUNTIF(C4:AG4, ">=1") -> 8 | AJ4: =COUNTIF(C4:AG4, "<0") -> 0
B5: Habit 2 | C5: 1 | D5: 1 | E5: 1 | F5: 1 | G5: 1 | H5: 1 | I5: 1 | J5: 1 | AI5: =COUNTIF(C5:AG5, ">=1") -> 8 | AJ5: =COUNTIF(C5:AG5, "<0") -> 0
B6: Habit 3 | C6: 1 | D6: 1 | E6: 1 | F6: 1 | G6: 1 | H6: 1 | I6: 1 | J6: 1 | AI6: =COUNTIF(C6:AG6, ">=1") -> 8 | AJ6: =COUNTIF(C6:AG6, "<0") -> 0
B7: Habit 4 | C7: 1 | D7: 1 | E7: 1 | F7: 1 | G7: 1 | H7: 1 | I7: 1 | J7: 1 | AI7: =COUNTIF(C7:AG7, ">=1") -> 8 | AJ7: =COUNTIF(C7:AG7, "<0") -> 0
B8: Habit 5 | C8: 1 | D8: 1 | E8: 1 | F8: 1 | G8: 1 | H8: 1 | I8: 1 | J8: 1 | M8: 1 | N8: -1 | AI8: =COUNTIF(C8:AG8, ">=1") -> 9 | AJ8: =COUNTIF(C8:AG8, "<0") -> 1
B9: Habit 6 | C9: 1 | D9: 1 | E9: 1 | F9: 1 | G9: 1 | H9: 1 | I9: 1 | J9: 1 | AI9: =COUNTIF(C9:AG9, ">=1") -> 8 | AJ9: =COUNTIF(C9:AG9, "<0") -> 0
B10: Habit 7 | C10: 1 | D10: 1 | E10: 1 | F10: 1 | G10: 1 | H10: 1 | I10: 1 | J10: 1 | AI10: =COUNTIF(C10:AG10, ">=1") -> 8 | AJ10: =COUNTIF(C10:AG10, "<0") -> 0
B11: Habit 8 | C11: 1 | D11: 1 | E11: 1 | F11: 1 | G11: 1 | H11: 1 | I11: 1 | J11: 1 | AI11: =COUNTIF(C11:AG11, ">=1") -> 8 | AJ11: =COUNTIF(C11:AG11, "<0") -> 0
B12: Habit 9 | C12: 1 | D12: 1 | E12: 1 | F12: 1 | G12: 1 | H12: 1 | I12: 1 | J12: 1 | AI12: =COUNTIF(C12:AG12, ">=1") -> 8 | AJ12: =COUNTIF(C12:AG12, "<0") -> 0
B13: Habit 10 | C13: 1 | D13: 1 | E13: 1 | F13: 1 | G13: 1 | H13: 1 | I13: 1 | J13: 1 | AI13: =COUNTIF(C13:AG13, ">=1") -> 8 | AJ13: =COUNTIF(C13:AG13, "<0") -> 0

Sheet MAY
B1: MAY
C3: 1 | D3: 2 | E3: 3 | F3: 4 | G3: 5 | H3: 6 | I3: 7 | J3: 8 | K3: 9 | L3: 10 | M3: 11 | N3: 12 | O3: 13 | P3: 14 | Q3: 15 | R3: 16 | S3: 17 | T3: 18 | U3: 19 | V3: 20 | W3: 21 | X3: 22 | Y3: 23 | Z3: 24 | AA3: 25 | AB3: 26 | AC3: 27 | AD3: 28 | AE3: 29 | AF3: 30 | AG3: 31 | AI3: YES | AJ3: NO
B4: {=habitlist} -> Habit 1 | C4: 1 | D4: 1 | E4: 1 | F4: 1 | G4: 1 | H4: 1 | I4: 1 | J4: 1 | AI4: =COUNTIF(C4:AG4, ">=1") -> 8 | AJ4: =COUNTIF(C4:AG4, "<0") -> 0
B5: Habit 2 | C5: 1 | D5: 1 | E5: 1 | F5: 1 | G5: 1 | H5: 1 | I5: 1 | J5: 1 | AI5: =COUNTIF(C5:AG5, ">=1") -> 8 | AJ5: =COUNTIF(C5:AG5, "<0") -> 0
B6: Habit 3 | C6: 1 | D6: 1 | E6: 1 | F6: 1 | G6: 1 | H6: 1 | I6: 1 | J6: 1 | AI6: =COUNTIF(C6:AG6, ">=1") -> 8 | AJ6: =COUNTIF(C6:AG6, "<0") -> 0
B7: Habit 4 | C7: 1 | D7: 1 | E7: 1 | F7: 1 | G7: 1 | H7: 1 | I7: 1 | J7: 1 | AI7: =COUNTIF(C7:AG7, ">=1") -> 8 | AJ7: =COUNTIF(C7:AG7, "<0") -> 0
B8: Habit 5 | C8: 1 | D8: 1 | E8: 1 | F8: 1 | G8: 1 | H8: 1 | I8: 1 | J8: 1 | AI8: =COUNTIF(C8:AG8, ">=1") -> 8 | AJ8: =COUNTIF(C8:AG8, "<0") -> 0
B9: Habit 6 | C9: 1 | D9: 1 | E9: 1 | F9: 1 | G9: 1 | H9: 1 | I9: 1 | J9: 1 | AI9: =COUNTIF(C9:AG9, ">=1") -> 8 | AJ9: =COUNTIF(C9:AG9, "<0") -> 0
B10: Habit 7 | C10: 1 | D10: 1 | E10: 1 | F10: 1 | G10: 1 | H10: 1 | I10: 1 | J10: 1 | AI10: =COUNTIF(C10:AG10, ">=1") -> 8 | AJ10: =COUNTIF(C10:AG10, "<0") -> 0
B11: Habit 8 | C11: 1 | D11: 1 | E11: 1 | F11: 1 | G11: 1 | H11: 1 | I11: 1 | J11: 1 | AI11: =COUNTIF(C11:AG11, ">=1") -> 8 | AJ11: =COUNTIF(C11:AG11, "<0") -> 0
B12: Habit 9 | C12: 1 | D12: 1 | E12: 1 | F12: 1 | G12: 1 | H12: 1 | I12: 1 | J12: 1 | AI12: =COUNTIF(C12:AG12, ">=1") -> 8 | AJ12: =COUNTIF(C12:AG12, "<0") -> 0
B13: Habit 10 | C13: 1 | D13: 1 | E13: 1 | F13: 1 | G13: 1 | H13: 1 | I13: 1 | J13: 1 | AI13: =COUNTIF(C13:AG13, ">=1") -> 8 | AJ13: =COUNTIF(C13:AG13, "<0") -> 0

Sheet JUN
B1: JUNE
C3: 1 | D3: 2 | E3: 3 | F3: 4 | G3: 5 | H3: 6 | I3: 7 | J3: 8 | K3: 9 | L3: 10 | M3: 11 | N3: 12 | O3: 13 | P3: 14 | Q3: 15 | R3: 16 | S3: 17 | T3: 18 | U3: 19 | V3: 20 | W3: 21 | X3: 22 | Y3: 23 | Z3: 24 | AA3: 25 | AB3: 26 | AC3: 27 | AD3: 28 | AE3: 29 | AF3: 30 | AG3: 31 | AI3: YES | AJ3: NO
B4: {=habitlist} -> Habit 1 | C4: 1 | D4: 1 | E4: 1 | F4: 1 | G4: 1 | H4: 1 | I4: 1 | J4: 1 | AI4: =COUNTIF(C4:AG4, ">=1") -> 8 | AJ4: =COUNTIF(C4:AG4, "<0") -> 0
B5: Habit 2 | C5: 1 | D5: 1 | E5: 1 | F5: 1 | G5: 1 | H5: 1 | I5: 1 | J5: 1 | AI5: =COUNTIF(C5:AG5, ">=1") -> 8 | AJ5: =COUNTIF(C5:AG5, "<0") -> 0
B6: Habit 3 | C6: 1 | D6: 1 | E6: 1 | F6: 1 | G6: 1 | H6: 1 | I6: 1 | J6: 1 | AI6: =COUNTIF(C6:AG6, ">=1") -> 8 | AJ6: =COUNTIF(C6:AG6, "<0") -> 0
B7: Habit 4 | C7: 1 | D7: 1 | E7: 1 | F7: 1 | G7: 1 | H7: 1 | I7: 1 | J7: 1 | AI7: =COUNTIF(C7:AG7, ">=1") -> 8 | AJ7: =COUNTIF(C7:AG7, "<0") -> 0
B8: Habit 5 | C8: 1 | D8: 1 | E8: 1 | F8: 1 | G8: 1 | H8: 1 | I8: 1 | J8: 1 | AI8: =COUNTIF(C8:AG8, ">=1") -> 8 | AJ8: =COUNTIF(C8:AG8, "<0") -> 0
B9: Habit 6 | C9: 1 | D9: 1 | E9: 1 | F9: 1 | G9: 1 | H9: 1 | I9: 1 | J9: 1 | AI9: =COUNTIF(C9:AG9, ">=1") -> 8 | AJ9: =COUNTIF(C9:AG9, "<0") -> 0
B10: Habit 7 | C10: 1 | D10: 1 | E10: 1 | F10: 1 | G10: 1 | H10: 1 | I10: 1 | J10: 1 | AI10: =COUNTIF(C10:AG10, ">=1") -> 8 | AJ10: =COUNTIF(C10:AG10, "<0") -> 0
B11: Habit 8 | C11: 1 | D11: 1 | E11: 1 | F11: 1 | G11: 1 | H11: 1 | I11: 1 | J11: 1 | AI11: =COUNTIF(C11:AG11, ">=1") -> 8 | AJ11: =COUNTIF(C11:AG11, "<0") -> 0
B12: Habit 9 | C12: 1 | D12: 1 | E12: 1 | F12: 1 | G12: 1 | H12: 1 | I12: 1 | J12: 1 | AI12: =COUNTIF(C12:AG12, ">=1") -> 8 | AJ12: =COUNTIF(C12:AG12, "<0") -> 0
B13: Habit 10 | C13: 1 | D13: 1 | E13: 1 | F13: 1 | G13: 1 | H13: 1 | I13: 1 | J13: 1 | AI13: =COUNTIF(C13:AG13, ">=1") -> 8 | AJ13: =COUNTIF(C13:AG13, "<0") -> 0

Sheet JUL
B1: JULY
C3: 1 | D3: 2 | E3: 3 | F3: 4 | G3: 5 | H3: 6 | I3: 7 | J3: 8 | K3: 9 | L3: 10 | M3: 11 | N3: 12 | O3: 13 | P3: 14 | Q3: 15 | R3: 16 | S3: 17 | T3: 18 | U3: 19 | V3: 20 | W3: 21 | X3: 22 | Y3: 23 | Z3: 24 | AA3: 25 | AB3: 26 | AC3: 27 | AD3: 28 | AE3: 29 | AF3: 30 | AG3: 31 | AI3: YES | AJ3: NO
B4: {=habitlist} -> Habit 1 | D4: 1 | E4: 1 | F4: 1 | G4: 1 | H4: 1 | I4: 1 | J4: 1 | K4: 1 | AI4: =COUNTIF(C4:AG4, ">=1") -> 8 | AJ4: =COUNTIF(C4:AG4, "<0") -> 0
B5: Habit 2 | D5: 1 | E5: 1 | F5: 1 | G5: 1 | H5: 1 | I5: 1 | J5: 1 | K5: 1 | AI5: =COUNTIF(C5:AG5, ">=1") -> 8 | AJ5: =COUNTIF(C5:AG5, "<0") -> 0
B6: Habit 3 | D6: 1 | E6: 1 | F6: 1 | G6: 1 | H6: 1 | I6: 1 | J6: 1 | K6: 1 | AI6: =COUNTIF(C6:AG6, ">=1") -> 8 | AJ6: =COUNTIF(C6:AG6, "<0") -> 0
B7: Habit 4 | D7: 1 | E7: 1 | F7: 1 | G7: 1 | H7: 1 | I7: 1 | J7: 1 | K7: 1 | AI7: =COUNTIF(C7:AG7, ">=1") -> 8 | AJ7: =COUNTIF(C7:AG7, "<0") -> 0
B8: Habit 5 | D8: 1 | E8: 1 | F8: 1 | G8: 1 | H8: 1 | I8: 1 | J8: 1 | K8: 1 | AI8: =COUNTIF(C8:AG8, ">=1") -> 8 | AJ8: =COUNTIF(C8:AG8, "<0") -> 0
B9: Habit 6 | D9: 1 | E9: 1 | F9: 1 | G9: 1 | H9: 1 | I9: 1 | J9: 1 | K9: 1 | AI9: =COUNTIF(C9:AG9, ">=1") -> 8 | AJ9: =COUNTIF(C9:AG9, "<0") -> 0
B10: Habit 7 | D10: 1 | E10: 1 | F10: 1 | G10: 1 | H10: 1 | I10: 1 | J10: 1 | K10: 1 | AI10: =COUNTIF(C10:AG10, ">=1") -> 8 | AJ10: =COUNTIF(C10:AG10, "<0") -> 0
B11: Habit 8 | D11: 1 | E11: 1 | F11: 1 | G11: 1 | H11: 1 | I11: 1 | J11: 1 | K11: 1 | AI11: =COUNTIF(C11:AG11, ">=1") -> 8 | AJ11: =COUNTIF(C11:AG11, "<0") -> 0
B12: Habit 9 | D12: 1 | E12: 1 | F12: 1 | G12: 1 | H12: 1 | I12: 1 | J12: 1 | K12: 1 | AI12: =COUNTIF(C12:AG12, ">=1") -> 8 | AJ12: =COUNTIF(C12:AG12, "<0") -> 0
B13: Habit 10 | D13: 1 | E13: 1 | F13: 1 | G13: 1 | H13: 1 | I13: 1 | J13: 1 | K13: 1 | AI13: =COUNTIF(C13:AG13, ">=1") -> 8 | AJ13: =COUNTIF(C13:AG13, "<0") -> 0

Sheet AUG
B1: AUGUST
C3: 1 | D3: 2 | E3: 3 | F3: 4 | G3: 5 | H3: 6 | I3: 7 | J3: 8 | K3: 9 | L3: 10 | M3: 11 | N3: 12 | O3: 13 | P3: 14 | Q3: 15 | R3: 16 | S3: 17 | T3: 18 | U3: 19 | V3: 20 | W3: 21 | X3: 22 | Y3: 23 | Z3: 24 | AA3: 25 | AB3: 26 | AC3: 27 | AD3: 28 | AE3: 29 | AF3: 30 | AG3: 31 | AI3: YES | AJ3: NO
B4: {=habitlist} -> Habit 1 | Y4: 1 | Z4: 1 | AA4: 1 | AB4: 1 | AC4: 1 | AD4: 1 | AE4: 1 | AF4: 1 | AI4: =COUNTIF(C4:AG4, ">=1") -> 8 | AJ4: =COUNTIF(C4:AG4, "<0") -> 0
B5: Habit 2 | Y5: 1 | Z5: 1 | AA5: 1 | AB5: 1 | AC5: 1 | AD5: 1 | AE5: 1 | AF5: 1 | AI5: =COUNTIF(C5:AG5, ">=1") -> 8 | AJ5: =COUNTIF(C5:AG5, "<0") -> 0
B6: Habit 3 | Y6: 1 | Z6: 1 | AA6: 1 | AB6: 1 | AC6: 1 | AD6: 1 | AE6: 1 | AF6: 1 | AI6: =COUNTIF(C6:AG6, ">=1") -> 8 | AJ6: =COUNTIF(C6:AG6, "<0") -> 0
B7: Habit 4 | Y7: 1 | Z7: 1 | AA7: 1 | AB7: 1 | AC7: 1 | AD7: 1 | AE7: 1 | AF7: 1 | AI7: =COUNTIF(C7:AG7, ">=1") -> 8 | AJ7: =COUNTIF(C7:AG7, "<0") -> 0
B8: Habit 5 | Y8: 1 | Z8: 1 | AA8: 1 | AB8: 1 | AC8: 1 | AD8: 1 | AE8: 1 | AF8: 1 | AI8: =COUNTIF(C8:AG8, ">=1") -> 8 | AJ8: =COUNTIF(C8:AG8, "<0") -> 0
B9: Habit 6 | Y9: 1 | Z9: 1 | AA9: 1 | AB9: 1 | AC9: 1 | AD9: 1 | AE9: 1 | AF9: 1 | AI9: =COUNTIF(C9:AG9, ">=1") -> 8 | AJ9: =COUNTIF(C9:AG9, "<0") -> 0
B10: Habit 7 | Y10: 1 | Z10: 1 | AA10: 1 | AB10: 1 | AC10: 1 | AD10: 1 | AE10: 1 | AF10: 1 | AI10: =COUNTIF(C10:AG10, ">=1") -> 8 | AJ10: =COUNTIF(C10:AG10, "<0") -> 0
B11: Habit 8 | Y11: 1 | Z11: 1 | AA11: 1 | AB11: 1 | AC11: 1 | AD11: 1 | AE11: 1 | AF11: 1 | AI11: =COUNTIF(C11:AG11, ">=1") -> 8 | AJ11: =COUNTIF(C11:AG11, "<0") -> 0
B12: Habit 9 | Y12: 1 | Z12: 1 | AA12: 1 | AB12: 1 | AC12: 1 | AD12: 1 | AE12: 1 | AF12: 1 | AI12: =COUNTIF(C12:AG12, ">=1") -> 8 | AJ12: =COUNTIF(C12:AG12, "<0") -> 0
B13: Habit 10 | Y13: 1 | Z13: 1 | AA13: 1 | AB13: 1 | AC13: 1 | AD13: 1 | AE13: 1 | AF13: 1 | AI13: =COUNTIF(C13:AG13, ">=1") -> 8 | AJ13: =COUNTIF(C13:AG13, "<0") -> 0

Sheet SEP
B1: SEPTEMBER
C3: 1 | D3: 2 | E3: 3 | F3: 4 | G3: 5 | H3: 6 | I3: 7 | J3: 8 | K3: 9 | L3: 10 | M3: 11 | N3: 12 | O3: 13 | P3: 14 | Q3: 15 | R3: 16 | S3: 17 | T3: 18 | U3: 19 | V3: 20 | W3: 21 | X3: 22 | Y3: 23 | Z3: 24 | AA3: 25 | AB3: 26 | AC3: 27 | AD3: 28 | AE3: 29 | AF3: 30 | AG3: 31 | AI3: YES | AJ3: NO
B4: {=habitlist} -> Habit 1 | E4: 1 | F4: 1 | G4: 1 | H4: 1 | I4: 1 | J4: 1 | K4: 1 | L4: 1 | AI4: =COUNTIF(C4:AG4, ">=1") -> 8 | AJ4: =COUNTIF(C4:AG4, "<0") -> 0
B5: Habit 2 | E5: 1 | F5: 1 | G5: 1 | H5: 1 | I5: 1 | J5: 1 | K5: 1 | L5: 1 | AI5: =COUNTIF(C5:AG5, ">=1") -> 8 | AJ5: =COUNTIF(C5:AG5, "<0") -> 0
B6: Habit 3 | E6: 1 | F6: 1 | G6: 1 | H6: 1 | I6: 1 | J6: 1 | K6: 1 | L6: 1 | AI6: =COUNTIF(C6:AG6, ">=1") -> 8 | AJ6: =COUNTIF(C6:AG6, "<0") -> 0
B7: Habit 4 | E7: 1 | F7: 1 | G7: 1 | H7: 1 | I7: 1 | J7: 1 | K7: 1 | L7: 1 | AI7: =COUNTIF(C7:AG7, ">=1") -> 8 | AJ7: =COUNTIF(C7:AG7, "<0") -> 0
B8: Habit 5 | E8: 1 | F8: 1 | G8: 1 | H8: 1 | I8: 1 | J8: 1 | K8: 1 | L8: 1 | AI8: =COUNTIF(C8:AG8, ">=1") -> 8 | AJ8: =COUNTIF(C8:AG8, "<0") -> 0
B9: Habit 6 | E9: 1 | F9: 1 | G9: 1 | H9: 1 | I9: 1 | J9: 1 | K9: 1 | L9: 1 | AI9: =COUNTIF(C9:AG9, ">=1") -> 8 | AJ9: =COUNTIF(C9:AG9, "<0") -> 0
B10: Habit 7 | E10: 1 | F10: 1 | G10: 1 | H10: 1 | I10: 1 | J10: 1 | K10: 1 | L10: 1 | AI10: =COUNTIF(C10:AG10, ">=1") -> 8 | AJ10: =COUNTIF(C10:AG10, "<0") -> 0
B11: Habit 8 | E11: 1 | F11: 1 | G11: 1 | H11: 1 | I11: 1 | J11: 1 | K11: 1 | L11: 1 | AI11: =COUNTIF(C11:AG11, ">=1") -> 8 | AJ11: =COUNTIF(C11:AG11, "<0") -> 0
B12: Habit 9 | E12: 1 | F12: 1 | G12: 1 | H12: 1 | I12: 1 | J12: 1 | K12: 1 | L12: 1 | AI12: =COUNTIF(C12:AG12, ">=1") -> 8 | AJ12: =COUNTIF(C12:AG12, "<0") -> 0
B13: Habit 10 | E13: 1 | F13: 1 | G13: 1 | H13: 1 | I13: 1 | J13: 1 | K13: 1 | L13: 1 | AI13: =COUNTIF(C13:AG13, ">=1") -> 8 | AJ13: =COUNTIF(C13:AG13, "<0") -> 0

Sheet OCT
B1: OCTOBER
C3: 1 | D3: 2 | E3: 3 | F3: 4 | G3: 5 | H3: 6 | I3: 7 | J3: 8 | K3: 9 | L3: 10 | M3: 11 | N3: 12 | O3: 13 | P3: 14 | Q3: 15 | R3: 16 | S3: 17 | T3: 18 | U3: 19 | V3: 20 | W3: 21 | X3: 22 | Y3: 23 | Z3: 24 | AA3: 25 | AB3: 26 | AC3: 27 | AD3: 28 | AE3: 29 | AF3: 30 | AG3: 31 | AI3: YES | AJ3: NO
B4: {=habitlist} -> Habit 1 | E4: 1 | F4: 1 | G4: 1 | H4: 1 | I4: 1 | J4: 1 | K4: 1 | L4: 1 | AI4: =COUNTIF(C4:AG4, ">=1") -> 8 | AJ4: =COUNTIF(C4:AG4, "<0") -> 0
B5: Habit 2 | E5: 1 | F5: 1 | G5: 1 | H5: 1 | I5: 1 | J5: 1 | K5: 1 | L5: 1 | AI5: =COUNTIF(C5:AG5, ">=1") -> 8 | AJ5: =COUNTIF(C5:AG5, "<0") -> 0
B6: Habit 3 | E6: 1 | F6: 1 | G6: 1 | H6: 1 | I6: 1 | J6: 1 | K6: 1 | L6: 1 | AI6: =COUNTIF(C6:AG6, ">=1") -> 8 | AJ6: =COUNTIF(C6:AG6, "<0") -> 0
B7: Habit 4 | E7: 1 | F7: 1 | G7: 1 | H7: 1 | I7: 1 | J7: 1 | K7: 1 | L7: 1 | AI7: =COUNTIF(C7:AG7, ">=1") -> 8 | AJ7: =COUNTIF(C7:AG7, "<0") -> 0
B8: Habit 5 | E8: 1 | F8: 1 | G8: 1 | H8: 1 | I8: 1 | J8: 1 | K8: 1 | L8: 1 | AI8: =COUNTIF(C8:AG8, ">=1") -> 8 | AJ8: =COUNTIF(C8:AG8, "<0") -> 0
B9: Habit 6 | E9: 1 | F9: 1 | G9: 1 | H9: 1 | I9: 1 | J9: 1 | K9: 1 | L9: 1 | AI9: =COUNTIF(C9:AG9, ">=1") -> 8 | AJ9: =COUNTIF(C9:AG9, "<0") -> 0
B10: Habit 7 | E10: 1 | F10: 1 | G10: 1 | H10: 1 | I10: 1 | J10: 1 | K10: 1 | L10: 1 | AI10: =COUNTIF(C10:AG10, ">=1") -> 8 | AJ10: =COUNTIF(C10:AG10, "<0") -> 0
B11: Habit 8 | E11: 1 | F11: 1 | G11: 1 | H11: 1 | I11: 1 | J11: 1 | K11: 1 | L11: 1 | AI11: =COUNTIF(C11:AG11, ">=1") -> 8 | AJ11: =COUNTIF(C11:AG11, "<0") -> 0
B12: Habit 9 | E12: 1 | F12: 1 | G12: 1 | H12: 1 | I12: 1 | J12: 1 | K12: 1 | L12: 1 | AI12: =COUNTIF(C12:AG12, ">=1") -> 8 | AJ12: =COUNTIF(C12:AG12, "<0") -> 0
B13: Habit 10 | E13: 1 | F13: 1 | G13: 1 | H13: 1 | I13: 1 | J13: 1 | K13: 1 | L13: 1 | AI13: =COUNTIF(C13:AG13, ">=1") -> 8 | AJ13: =COUNTIF(C13:AG13, "<0") -> 0

Sheet NOV
B1: NOVEMBER
C3: 1 | D3: 2 | E3: 3 | F3: 4 | G3: 5 | H3: 6 | I3: 7 | J3: 8 | K3: 9 | L3: 10 | M3: 11 | N3: 12 | O3: 13 | P3: 14 | Q3: 15 | R3: 16 | S3: 17 | T3: 18 | U3: 19 | V3: 20 | W3: 21 | X3: 22 | Y3: 23 | Z3: 24 | AA3: 25 | AB3: 26 | AC3: 27 | AD3: 28 | AE3: 29 | AF3: 30 | AG3: 31 | AI3: YES | AJ3: NO
B4: {=habitlist} -> Habit 1 | S4: 1 | T4: 1 | U4: 1 | V4: 1 | W4: 1 | X4: 1 | Y4: 1 | Z4: 1 | AI4: =COUNTIF(C4:AG4, ">=1") -> 8 | AJ4: =COUNTIF(C4:AG4, "<0") -> 0
B5: Habit 2 | S5: 1 | T5: 1 | U5: 1 | V5: 1 | W5: 1 | X5: 1 | Y5: 1 | Z5: 1 | AI5: =COUNTIF(C5:AG5, ">=1") -> 8 | AJ5: =COUNTIF(C5:AG5, "<0") -> 0
B6: Habit 3 | S6: 1 | T6: 1 | U6: 1 | V6: 1 | W6: 1 | X6: 1 | Y6: 1 | Z6: 1 | AI6: =COUNTIF(C6:AG6, ">=1") -> 8 | AJ6: =COUNTIF(C6:AG6, "<0") -> 0
B7: Habit 4 | S7: 1 | T7: 1 | U7: 1 | V7: 1 | W7: 1 | X7: 1 | Y7: 1 | Z7: 1 | AI7: =COUNTIF(C7:AG7, ">=1") -> 8 | AJ7: =COUNTIF(C7:AG7, "<0") -> 0
B8: Habit 5 | S8: 1 | T8: 1 | U8: 1 | V8: 1 | W8: 1 | X8: 1 | Y8: 1 | Z8: 1 | AI8: =COUNTIF(C8:AG8, ">=1") -> 8 | AJ8: =COUNTIF(C8:AG8, "<0") -> 0
B9: Habit 6 | S9: 1 | T9: 1 | U9: 1 | V9: 1 | W9: 1 | X9: 1 | Y9: 1 | Z9: 1 | AI9: =COUNTIF(C9:AG9, ">=1") -> 8 | AJ9: =COUNTIF(C9:AG9, "<0") -> 0
B10: Habit 7 | S10: 1 | T10: 1 | U10: 1 | V10: 1 | W10: 1 | X10: 1 | Y10: 1 | Z10: 1 | AI10: =COUNTIF(C10:AG10, ">=1") -> 8 | AJ10: =COUNTIF(C10:AG10, "<0") -> 0
B11: Habit 8 | S11: 1 | T11: 1 | U11: 1 | V11: 1 | W11: 1 | X11: 1 | Y11: 1 | Z11: 1 | AI11: =COUNTIF(C11:AG11, ">=1") -> 8 | AJ11: =COUNTIF(C11:AG11, "<0") -> 0
B12: Habit 9 | S12: 1 | T12: 1 | U12: 1 | V12: 1 | W12: 1 | X12: 1 | Y12: 1 | Z12: 1 | AI12: =COUNTIF(C12:AG12, ">=1") -> 8 | AJ12: =COUNTIF(C12:AG12, "<0") -> 0
B13: Habit 10 | S13: 1 | T13: 1 | U13: 1 | V13: 1 | W13: 1 | X13: 1 | Y13: 1 | Z13: 1 | AI13: =COUNTIF(C13:AG13, ">=1") -> 8 | AJ13: =COUNTIF(C13:AG13, "<0") -> 0

Sheet DEC
B1: DECEMBER
C3: 1 | D3: 2 | E3: 3 | F3: 4 | G3: 5 | H3: 6 | I3: 7 | J3: 8 | K3: 9 | L3: 10 | M3: 11 | N3: 12 | O3: 13 | P3: 14 | Q3: 15 | R3: 16 | S3: 17 | T3: 18 | U3: 19 | V3: 20 | W3: 21 | X3: 22 | Y3: 23 | Z3: 24 | AA3: 25 | AB3: 26 | AC3: 27 | AD3: 28 | AE3: 29 | AF3: 30 | AG3: 31 | AI3: YES | AJ3: NO
B4: {=habitlist} -> Habit 1 | V4: 1 | W4: 1 | X4: 1 | Y4: 1 | Z4: 1 | AA4: 1 | AB4: 1 | AC4: 1 | AI4: =COUNTIF(C4:AG4, ">=1") -> 8 | AJ4: =COUNTIF(C4:AG4, "<0") -> 0
B5: Habit 2 | V5: 1 | W5: 1 | X5: 1 | Y5: 1 | Z5: 1 | AA5: 1 | AB5: 1 | AC5: 1 | AI5: =COUNTIF(C5:AG5, ">=1") -> 8 | AJ5: =COUNTIF(C5:AG5, "<0") -> 0
B6: Habit 3 | V6: 1 | W6: 1 | X6: 1 | Y6: 1 | Z6: 1 | AA6: 1 | AB6: 1 | AC6: 1 | AI6: =COUNTIF(C6:AG6, ">=1") -> 8 | AJ6: =COUNTIF(C6:AG6, "<0") -> 0
B7: Habit 4 | V7: 1 | W7: 1 | X7: 1 | Y7: 1 | Z7: 1 | AA7: 1 | AB7: 1 | AC7: 1 | AI7: =COUNTIF(C7:AG7, ">=1") -> 8 | AJ7: =COUNTIF(C7:AG7, "<0") -> 0
B8: Habit 5 | V8: 1 | W8: 1 | X8: 1 | Y8: 1 | Z8: 1 | AA8: 1 | AB8: 1 | AC8: 1 | AI8: =COUNTIF(C8:AG8, ">=1") -> 8 | AJ8: =COUNTIF(C8:AG8, "<0") -> 0
B9: Habit 6 | V9: 1 | W9: 1 | X9: 1 | Y9: 1 | Z9: 1 | AA9: 1 | AB9: 1 | AC9: 1 | AI9: =COUNTIF(C9:AG9, ">=1") -> 8 | AJ9: =COUNTIF(C9:AG9, "<0") -> 0
B10: Habit 7 | V10: 1 | W10: 1 | X10: 1 | Y10: 1 | Z10: 1 | AA10: 1 | AB10: 1 | AC10: 1 | AI10: =COUNTIF(C10:AG10, ">=1") -> 8 | AJ10: =COUNTIF(C10:AG10, "<0") -> 0
B11: Habit 8 | V11: 1 | W11: 1 | X11: 1 | Y11: 1 | Z11: 1 | AA11: 1 | AB11: 1 | AC11: 1 | AI11: =COUNTIF(C11:AG11, ">=1") -> 8 | AJ11: =COUNTIF(C11:AG11, "<0") -> 0
B12: Habit 9 | V12: 1 | W12: 1 | X12: 1 | Y12: 1 | Z12: 1 | AA12: 1 | AB12: 1 | AC12: 1 | AI12: =COUNTIF(C12:AG12, ">=1") -> 8 | AJ12: =COUNTIF(C12:AG12, "<0") -> 0
B13: Habit 10 | V13: 1 | W13: 1 | X13: 1 | Y13: 1 | Z13: 1 | AA13: 1 | AB13: 1 | AC13: 1 | AI13: =COUNTIF(C13:AG13, ">=1") -> 8 | AJ13: =COUNTIF(C13:AG13, "<0") -> 0
